Workbook

Sheet Inputs
B1: Meridian Industrial Corp. (illustrative): DCF inputs
B2: ($in millions, except per-share data)
B3: Blue = hard-coded input, black = formula, green = link to another sheet
B5: General
B6: Base fiscal year (valuation date = year end) | C6: 2025
B7: Mid-year convention (1 = on, 0 = off) | C7: 1
B8: Tax rate | C8: 0.24
B10: Base year
B11: Revenue | C11: 2400
B12: Net working capital | C12: 285
B14: Terminal value
B15: Terminal (perpetuity) growth rate | C15: 0.025
B16: Exit EV/EBITDA multiple | C16: 10
B18: Equity bridge
B19: Total debt | C19: 900
B20: Preferred equity | C20: 0
B21: Minority (non-controlling) interest | C21: 40
B22: Cash and equivalents | C22: 250
B23: Non-operating assets (e.g. investments) | C23: 60
B25: Shares
B26: Basic shares outstanding | C26: 120
B27: RSUs / restricted stock (fully dilutive) | C27: 1.5
B28: Current share price ($) | C28: 38.5
B30: Options (keep sorted by ascending strike) | C30: Count | D30: Strike
B31: Tranche 1 | C31: 3 | D31: 25
B32: Tranche 2 | C32: 2.5 | D32: 40
B33: Tranche 3 | C33: 1 | D33: 60

Sheet WACC
B1: Meridian Industrial Corp. (illustrative): weighted average cost of capital
B2: CAPM cost of equity, Hamada relevering
B4: Cost of capital
B5: Risk-free rate | C5: 0.0425
B6: Equity risk premium | C6: 0.055
B7: Unlevered beta | C7: 0.95
B8: Size premium | C8: 0.005
B9: Target debt / total capital | C9: 0.25
B10: Pre-tax cost of debt | C10: 0.06
B11: Tax rate | C11: =Inputs!$C$8
B13: Target debt / equity | C13: =$C$9/(1-$C$9)
B14: Levered beta = βu × (1 + (1 − t) × D/E) | C14: =$C$7*(1+(1-$C$11)*$C$13)
B15: Cost of equity = rf + βL × ERP + size | C15: =$C$5+$C$14*$C$6+$C$8
B16: After-tax cost of debt = kd × (1 − t) | C16: =$C$10*(1-$C$11)
B17: Equity weight | C17: =1-$C$9
B18: Debt weight | C18: =$C$9
B19: WACC | C19: =$C$17*$C$15+$C$18*$C$16

Sheet DCF
B1: Meridian Industrial Corp. (illustrative): discounted cash flow analysis
B2: ($in millions, except per-share data)
B4: Unlevered free cash flow | C4: FY2025A | D4: FY2026E | E4: FY2027E | F4: FY2028E | G4: FY2029E | H4: FY2030E
B5: Revenue growth | D5: 0.08 | E5: 0.075 | F5: 0.065 | G5: 0.055 | H5: 0.045
B6: Revenue | C6: =Inputs!$C$11 | D6: =C6*(1+D5) | E6: =D6*(1+E5) | F6: =E6*(1+F5) | G6: =F6*(1+G5) | H6: =G6*(1+H5)
B7: EBITDA margin | D7: 0.21 | E7: 0.215 | F7: 0.22 | G7: 0.225 | H7: 0.23
B8: EBITDA | D8: =D6*D7 | E8: =E6*E7 | F8: =F6*F7 | G8: =G6*G7 | H8: =H6*H7
B9: D&A, % of revenue | D9: 0.04 | E9: 0.04 | F9: 0.04 | G9: 0.04 | H9: 0.04
B10: Less: D&A | D10: =D6*D9 | E10: =E6*E9 | F10: =F6*F9 | G10: =G6*G9 | H10: =H6*H9
B11: EBIT | D11: =D8-D10 | E11: =E8-E10 | F11: =F8-F10 | G11: =G8-G10 | H11: =H8-H10
B12: Less: taxes on EBIT = t × max(EBIT, 0) | D12: =MAX(D11,0)*Inputs!$C$8 | E12: =MAX(E11,0)*Inputs!$C$8 | F12: =MAX(F11,0)*Inputs!$C$8 | G12: =MAX(G11,0)*Inputs!$C$8 | H12: =MAX(H11,0)*Inputs!$C$8
B13: NOPAT | D13: =D11-D12 | E13: =E11-E12 | F13: =F11-F12 | G13: =G11-G12 | H13: =H11-H12
B14: Plus: D&A | D14: =D10 | E14: =E10 | F14: =F10 | G14: =G10 | H14: =H10
B15: CapEx, % of revenue | D15: 0.05 | E15: 0.048 | F15: 0.046 | G15: 0.044 | H15: 0.042
B16: Less: capital expenditures | D16: =D6*D15 | E16: =E6*E15 | F16: =F6*F15 | G16: =G6*G15 | H16: =H6*H15
B17: NWC, % of revenue | D17: 0.12 | E17: 0.12 | F17: 0.12 | G17: 0.12 | H17: 0.12
B18: Net working capital | C18: =Inputs!$C$12 | D18: =D6*D17 | E18: =E6*E17 | F18: =F6*F17 | G18: =G6*G17 | H18: =H6*H17
B19: Less: increase in NWC | D19: =D18-C18 | E19: =E18-D18 | F19: =F18-E18 | G19: =G18-F18 | H19: =H18-G18
B20: Unlevered free cash flow | D20: =D13+D14-D16-D19 | E20: =E13+E14-E16-E19 | F20: =F13+F14-F16-F19 | G20: =G13+G14-G16-G19 | H20: =H13+H14-H16-H19
B22: Year | D22: =1 | E22: =D22+1 | F22: =E22+1 | G22: =F22+1 | H22: =G22+1
B23: Discount period (years) | D23: =IF(Inputs!$C$7=1,D22-0.5,D22) | E23: =IF(Inputs!$C$7=1,E22-0.5,E22) | F23: =IF(Inputs!$C$7=1,F22-0.5,F22) | G23: =IF(Inputs!$C$7=1,G22-0.5,G22) | H23: =IF(Inputs!$C$7=1,H22-0.5,H22)
B24: Discount factor | D24: =1/(1+WACC!$C$19)^D23 | E24: =1/(1+WACC!$C$19)^E23 | F24: =1/(1+WACC!$C$19)^F23 | G24: =1/(1+WACC!$C$19)^G23 | H24: =1/(1+WACC!$C$19)^H23
B25: PV of unlevered free cash flow | D25: =D20*D24 | E25: =E20*E24 | F25: =F20*F24 | G25: =G20*G24 | H25: =H20*H24
B27: Terminal value and enterprise value | C27: Perpetuity | D27: Exit multiple
B28: WACC | C28: =WACC!$C$19 | D28: =WACC!$C$19
B29: Terminal growth rate | C29: =Inputs!$C$15
B30: Exit EV/EBITDA multiple | D30: =Inputs!$C$16
B31: Final-year UFCF / final-year EBITDA | C31: =$H$20 | D31: =$H$8
B32: Terminal value | C32: =C31*(1+C29)/(C28-C29) | D32: =D31*D30
B33: Terminal value discount period | C33: =IF(Inputs!$C$7=1,$H$22-0.5,$H$22) | D33: =$H$22
B34: PV of terminal value | C34: =C32/(1+C28)^C33 | D34: =D32/(1+D28)^D33
B35: Sum of PV of UFCF | C35: =SUM($D$25:$H$25) | D35: =SUM($D$25:$H$25)
B36: Enterprise value | C36: =C35+C34 | D36: =D35+D34
B37: PV of terminal value, % of EV | C37: =C34/C36 | D37: =D34/D36
B38: Implied exit multiple / implied perpetuity growth | C38: =IF($H$8>0,C32*(1+C28)^($H$22-C33)/$H$8,NA()) | D38: =IF($H$20>0,(D32/($H$20*(1+D28)^($H$22-C33))*D28-1)/(D32/($H$20*(1+D28)^($H$22-C33))+1),NA())
B40: Equity value and implied share price
B41: Less: total debt | C41: =Inputs!$C$19 | D41: =Inputs!$C$19
B42: Less: preferred equity | C42: =Inputs!$C$20 | D42: =Inputs!$C$20
B43: Less: minority interest | C43: =Inputs!$C$21 | D43: =Inputs!$C$21
B44: Plus: cash | C44: =Inputs!$C$22 | D44: =Inputs!$C$22
...

Sheet Sensitivity
B1: Meridian Industrial Corp. (illustrative): sensitivity analysis
B2: Values computed by dcfmodel (Python). Rerun dcfmodel after changing inputs to refresh.
B4: Implied share price: perpetuity growth method
B5: WACC ↓ Terminal growth rate → | C5: 0.015 | D5: 0.02 | E5: 0.025 | F5: 0.03 | G5: 0.035
B6: 0.08614 | C6: 42.781919 | D6: 45.595159 | E6: 48.86853 | F6: 52.724974 | G6: 57.335513
B7: 0.09114 | C7: 39.692053 | D7: 42.102903 | E7: 44.871282 | F7: 48.092453 | G7: 51.8874
B8: 0.09614 | C8: 36.935538 | D8: 39.052147 | E8: 41.437419 | F8: 44.161852 | G8: 47.33189
B9: 0.10114 | C9: 34.500427 | D9: 36.341753 | E9: 38.424914 | F9: 40.785134 | G9: 43.466514
B10: 0.10614 | C10: 32.333791 | D10: 33.947296 | E10: 35.759655 | F10: 37.810045 | G10: 40.145727
B12: Implied share price: exit multiple method
B13: WACC ↓ Exit EV/EBITDA multiple → | C13: 8 | D13: 9 | E13: 10 | F13: 11 | G13: 12
B14: 0.08614 | C14: 39.350906 | D14: 43.28342 | E14: 47.203157 | F14: 51.122894 | G14: 55.04263
B15: 0.09114 | C15: 38.486534 | D15: 42.347075 | E15: 46.177822 | F15: 50.00857 | G15: 53.839318
B16: 0.09614 | C16: 37.644571 | D16: 41.43511 | E16: 45.179282 | F16: 48.923454 | G16: 52.667626
B17: 0.10114 | C17: 36.824327 | D17: 40.546774 | E17: 44.206708 | F17: 47.866642 | G17: 51.526576
B18: 0.10614 | C18: 36.025138 | D18: 39.674945 | E18: 43.259303 | F18: 46.837263 | G18: 50.415222
